Workbook

Sheet Resumen
A1: Resumen de ejecución · Angie Tech
A2: Fecha: 2026-10-12 · Fuente: hoja de casos de uso compartida por la usuaria · Los conteos se calculan con fórmulas sobre la hoja «Casos de prueba».
A4: Estado | B4: Casos | C4: %
A5: Aprobado | B5: =COUNTIF('Casos de prueba'!$J$2:$J$108,A5) -> 92 | C5: =IFERROR(B5/$B$10,0) -> 0.85981308
A6: Corregido | B6: =COUNTIF('Casos de prueba'!$J$2:$J$108,A6) -> 14 | C6: =IFERROR(B6/$B$10,0) -> 0.13084112
A7: Corregido (falta ejecutar SQL 05) | B7: =COUNTIF('Casos de prueba'!$J$2:$J$108,A7) -> 0 | C7: =IFERROR(B7/$B$10,0) -> 0
A8: Fallido | B8: =COUNTIF('Casos de prueba'!$J$2:$J$108,A8) -> 0 | C8: =IFERROR(B8/$B$10,0) -> 0
A9: No ejecutado | B9: =COUNTIF('Casos de prueba'!$J$2:$J$108,A9) -> 1 | C9: =IFERROR(B9/$B$10,0) -> 0.0093457944
A10: Total | B10: =SUM(B5:B9) -> 107 | C10: =SUM(C5:C9) -> 1
A12: Módulo | B12: Casos | C12: Aprobados | D12: Corregidos | E12: Fallidos / no ejecutados
A13: Autenticación y permisos | B13: =COUNTIF('Casos de prueba'!$B$2:$B$108,A13) -> 10 | C13: =COUNTIFS('Casos de prueba'!$B$2:$B$108,A13,'Casos de prueba'!$J$2:$J$108,"Aprobado") -> 9 | D13: =COUNTIFS('Casos de prueba'!$B$2:$B$108,A13,'Casos de prueba'!$J$2:$J$108,"Corregido*") -> 1 | E13: =B13-C13-D13 -> 0
A14: Dashboard e Inicio | B14: =COUNTIF('Casos de prueba'!$B$2:$B$108,A14) -> 12 | C14: =COUNTIFS('Casos de prueba'!$B$2:$B$108,A14,'Casos de prueba'!$J$2:$J$108,"Aprobado") -> 11 | D14: =COUNTIFS('Casos de prueba'!$B$2:$B$108,A14,'Casos de prueba'!$J$2:$J$108,"Corregido*") -> 1 | E14: =B14-C14-D14 -> 0
A15: Inventario | B15: =COUNTIF('Casos de prueba'!$B$2:$B$108,A15) -> 18 | C15: =COUNTIFS('Casos de prueba'!$B$2:$B$108,A15,'Casos de prueba'!$J$2:$J$108,"Aprobado") -> 18 | D15: =COUNTIFS('Casos de prueba'!$B$2:$B$108,A15,'Casos de prueba'!$J$2:$J$108,"Corregido*") -> 0 | E15: =B15-C15-D15 -> 0
A16: Ventas y carrito | B16: =COUNTIF('Casos de prueba'!$B$2:$B$108,A16) -> 14 | C16: =COUNTIFS('Casos de prueba'!$B$2:$B$108,A16,'Casos de prueba'!$J$2:$J$108,"Aprobado") -> 12 | D16: =COUNTIFS('Casos de prueba'!$B$2:$B$108,A16,'Casos de prueba'!$J$2:$J$108,"Corregido*") -> 2 | E16: =B16-C16-D16 -> 0
A17: Facturación | B17: =COUNTIF('Casos de prueba'!$B$2:$B$108,A17) -> 15 | C17: =COUNTIFS('Casos de prueba'!$B$2:$B$108,A17,'Casos de prueba'!$J$2:$J$108,"Aprobado") -> 12 | D17: =COUNTIFS('Casos de prueba'!$B$2:$B$108,A17,'Casos de prueba'!$J$2:$J$108,"Corregido*") -> 3 | E17: =B17-C17-D17 -> 0
A18: Clientes | B18: =COUNTIF('Casos de prueba'!$B$2:$B$108,A18) -> 8 | C18: =COUNTIFS('Casos de prueba'!$B$2:$B$108,A18,'Casos de prueba'!$J$2:$J$108,"Aprobado") -> 7 | D18: =COUNTIFS('Casos de prueba'!$B$2:$B$108,A18,'Casos de prueba'!$J$2:$J$108,"Corregido*") -> 1 | E18: =B18-C18-D18 -> 0
A19: Empleados y permisos | B19: =COUNTIF('Casos de prueba'!$B$2:$B$108,A19) -> 8 | C19: =COUNTIFS('Casos de prueba'!$B$2:$B$108,A19,'Casos de prueba'!$J$2:$J$108,"Aprobado") -> 7 | D19: =COUNTIFS('Casos de prueba'!$B$2:$B$108,A19,'Casos de prueba'!$J$2:$J$108,"Corregido*") -> 1 | E19: =B19-C19-D19 -> 0
A20: Proveedores y compras | B20: =COUNTIF('Casos de prueba'!$B$2:$B$108,A20) -> 6 | C20: =COUNTIFS('Casos de prueba'!$B$2:$B$108,A20,'Casos de prueba'!$J$2:$J$108,"Aprobado") -> 6 | D20: =COUNTIFS('Casos de prueba'!$B$2:$B$108,A20,'Casos de prueba'!$J$2:$J$108,"Corregido*") -> 0 | E20: =B20-C20-D20 -> 0
A21: Interfaz y experiencia | B21: =COUNTIF('Casos de prueba'!$B$2:$B$108,A21) -> 10 | C21: =COUNTIFS('Casos de prueba'!$B$2:$B$108,A21,'Casos de prueba'!$J$2:$J$108,"Aprobado") -> 5 | D21: =COUNTIFS('Casos de prueba'!$B$2:$B$108,A21,'Casos de prueba'!$J$2:$J$108,"Corregido*") -> 4 | E21: =B21-C21-D21 -> 1
A22: Integridad y seguridad transversal | B22: =COUNTIF('Casos de prueba'!$B$2:$B$108,A22) -> 6 | C22: =COUNTIFS('Casos de prueba'!$B$2:$B$108,A22,'Casos de prueba'!$J$2:$J$108,"Aprobado") -> 5 | D22: =COUNTIFS('Casos de prueba'!$B$2:$B$108,A22,'Casos de prueba'!$J$2:$J$108,"Corregido*") -> 1 | E22: =B22-C22-D22 -> 0

Sheet Casos de prueba
A1: ID | B1: Módulo | C1: Caso de prueba | D1: Precondiciones / datos | E1: Pasos de ejecución | F1: Resultado esperado | G1: Prioridad | H1: Rol | I1: Tipo | J1: Estado | K1: Resultado obtenido | L1: Evidencia / defecto | M1: Ejecutado por | N1: Fecha de ejecución
A2: AUT-001 | B2: Autenticación y permisos | C2: Inicio de sesión válido como administrador | D2: Administrador activo. | E2: Abrir login; ingresar credenciales válidas; entrar. | F2: Accede al Inicio administrativo y ve módulos autorizados. | G2: Crítica | H2: Administrador | I2: Funcional | J2: Aprobado | K2: UI: entra al Inicio administrativo «Administrador · Controla tu negocio» con módulos Inventario, Facturación, Clientes, Ventas, Ingresos, Gastos. | L2: Navegador localhost:5173 | M2: Claude (QA automatizado) | N2: 2026-10-12
A3: AUT-002 | B3: Autenticación y permisos | C3: Inicio de sesión válido como vendedor | D3: Vendedor activo. | E3: Abrir login; ingresar credenciales válidas; entrar. | F3: Accede al Inicio de vendedor sin información administrativa. | G3: Crítica | H3: Vendedor | I3: Funcional | J3: Aprobado | K3: UI: entra a Inicio de vendedor «Vende de forma rápida»; sin ingresos globales, gastos, utilidad ni comisiones. | L3: Navegador | M3: Claude (QA automatizado) | N3: 2026-10-12
A4: AUT-003 | B4: Autenticación y permisos | C4: Contraseña incorrecta | D4: Usuario de QA existente. | E4: Ingresar correo válido y contraseña incorrecta. | F4: Deniega acceso y muestra mensaje claro. | G4: Alta | H4: Ambos | I4: Seguridad | J4: Aprobado | K4: HTTP 400: Invalid login credentials; UI traduce a «Correo o contraseña incorrectos.» | L4: mensajeError() en format.js | M4: Claude (QA automatizado) | N4: 2026-10-12
A5: AUT-004 | B5: Autenticación y permisos | C5: Campos obligatorios vacíos | D5: Pantalla de login. | E5: Enviar formulario vacío. | F5: Indica campos obligatorios y no inicia sesión. | G5: Alta | H5: Ambos | I5: Funcional | J5: Aprobado | K5: Formulario vacío: el navegador marca «Completa este campo» en correo y contraseña; no inicia sesión (sigue en /login). | L5: validación required | M5: Claude (QA automatizado) | N5: 2026-10-12
A6: AUT-005 | B6: Autenticación y permisos | C6: Cerrar sesión | D6: Sesión iniciada. | E6: Cerrar sesión e intentar volver con Atrás. | F6: La sesión termina y las pantallas privadas exigen autenticación. | G6: Crítica | H6: Ambos | I6: Seguridad | J6: Aprobado | K6: Cerrar sesión → /login; Atrás → /login; abrir /facturas directo → /login; no queda token guardado. | L6: ProtectedRoute | M6: Claude (QA automatizado) | N6: 2026-10-12
A7: AUT-006 | B7: Autenticación y permisos | C7: Vendedor abre ruta administrativa | D7: Sesión de vendedor; ruta conocida. | E7: Abrir URL administrativa y probar API si aplica. | F7: Deniega acceso en interfaz y servidor; no filtra datos. | G7: Crítica | H7: Vendedor | I7: Seguridad | J7: Aprobado | K7: movimientos:0; compras:0; pagos_proveedor:0; actividad:0; compra_items:0; movimientos_inventario:0; resumen_dashboard:400; productos(costos):0 | L7: API REST con token de vendedor | M7: Claude (QA automatizado) | N7: 2026-10-12
A8: AUT-007 | B8: Autenticación y permisos | C8: Vendedor intenta editar precio o stock | D8: Vendedor sin permiso. | E8: Intentar editar desde UI y solicitud directa. | F8: Operación rechazada en servidor; datos intactos. | G8: Crítica | H8: Vendedor | I8: Seguridad | J8: Aprobado | K8: PATCH precio → 200 filas=0; ajuste → 400 «No tienes permiso para modificar el inventario»; PATCH stock → 200; precio y stock intactos (3650000, 0) | L8: UI vendedor sin Editar/Cargar | M8: Claude (QA automatizado) | N8: 2026-10-12
A9: AUT-008 | B9: Autenticación y permisos | C9: Recuperación de contraseña | D9: Correo de QA habilitado. | E9: Solicitar recuperación y completar el flujo. | F9: Flujo funciona sin revelar datos sensibles de cuentas. | G9: Media | H9: Ambos | I9: Funcional | J9: Corregido | K9: Antes no existía: «¿Olvidaste tu contraseña?» solo decía «pídele al administrador», que no tenía cómo hacerlo. Ahora envía un enlace al correo y la página /restablecer permite crear la contraseña nueva (mínimo 8, confirmación). No revela si el correo existe. Probado hasta la pantalla de nueva contraseña; el correo real no se envió. | L9: Login.jsx, Restablecer.jsx. Requiere en Supabase > Authentication > URL Configuration agregar la URL de la app + /restablecer. | M9: Claude (QA automatizado) | N9: 2026-10-12
A10: AUT-009 | B10: Autenticación y permisos | C10: Acceso de empleado desactivado | D10: Empleado desactivado. | E10: Intentar iniciar sesión y usar sesión previa. | F10: Se bloquea el acceso según política de sesiones. | G10: Crítica | H10: Administrador | I10: Seguridad | J10: Aprobado | K10: Igual que EMP-002: el acceso a datos y operaciones queda bloqueado al instante, también con la sesión ya abierta. | M10: Claude (QA automatizado) | N10: 2026-10-12
A11: AUT-010 | B11: Autenticación y permisos | C11: Sesión expirada | D11: Token/sesión expirados en QA. | E11: Intentar navegar o guardar tras expirar. | F11: Solicita autenticación y no ejecuta operaciones protegidas. | G11: Alta | H11: Ambos | I11: Seguridad | J11: Aprobado | K11: Lectura con token vencido → 401 «JWT cryptographic operation failed»; emitir factura → 401 | L11: supabase-js refresca o devuelve a /login | M11: Claude (QA automatizado) | N11: 2026-10-12
A12: DAS-001 | B12: Dashboard e Inicio | C12: Ventas del día | D12: Ventas en distintas fechas. | E12: Consultar total del día. | F12: Coincide con ventas del día y regla definida de estados. | G12: Alta | H12: Administrador | I12: Funcional | J12: Aprobado | K12: Dashboard hoy 26305000 / 3 facturas = recálculo 26305000 / 3 (solo emitidas, neto de devoluciones) | L12: resumen_dashboard vs facturas_netas | M12: Claude (QA automatizado) | N12: 2026-10-12
A13: DAS-002 | B13: Dashboard e Inicio | C13: Filtro de ventas día/mes/año | D13: Ventas en varios períodos. | E13: Cambiar filtro y comparar resultados. | F13: Importe y contador corresponden al período seleccionado. | G13: Alta | H13: Administrador | I13: Funcional | J13: Aprobado | K13: Mes 75770000 (18 fact.), año 75770000; dashboard mes 75770000 | L13: Recálculo por período | M13: Claude (QA automatizado) | N13: 2026-10-12
A14: DAS-003 | B14: Dashboard e Inicio | C14: Ingresos y gastos | D14: Movimientos registrados. | E14: Comparar métricas con registros fuente. | F14: Valores correctos y no confundidos con ventas. | G14: Alta | H14: Administrador | I14: Funcional | J14: Aprobado | K14: Ingreso 7.000 → ingresos +7000; gasto 3.000 → gastos +3000; ventas sin cambio (+0). Movimientos QA eliminados. | L14: resumen_dashboard | M14: Claude (QA automatizado) | N14: 2026-10-12
A15: DAS-004 | B15: Dashboard e Inicio | C15: Valor del inventario | D15: Productos con costos y stock diferentes. | E15: Consultar total y comparar fórmula acordada. | F15: Valor corresponde a regla aprobada, por ejemplo costo × stock. | G15: Alta | H15: Administrador | I15: Funcional | J15: Aprobado | K15: Valor inventario 24993500 = Σ costo × stock (24993500) | L15: Fórmula costo × stock de productos activos | M15: Claude (QA automatizado) | N15: 2026-10-12
A16: DAS-005 | B16: Dashboard e Inicio | C16: Productos con stock bajo | D16: Productos debajo, igual y encima del mínimo. | E16: Consultar sección de stock bajo. | F16: Lista solo productos que cumplen la regla de mínimo. | G16: Alta | H16: Administrador | I16: Funcional | J16: Aprobado | K16: 2 productos con stock ≤ mínimo (recálculo 2) | L16: vista stock_bajo | M16: Claude (QA automatizado) | N16: 2026-10-12
A17: DAS-006 | B17: Dashboard e Inicio | C17: Ventas por empleado | D17: Dos vendedores con ventas. | E17: Filtrar reporte por período. | F17: Totales correctos por vendedor. | G17: Alta | H17: Administrador | I17: Funcional | J17: Aprobado | K17: Administrador de prueba: 41055000 (11 fact.); Vendedor de prueba: 28860000 (5 fact.); José Aldana: 5855000 (2 fact.) = recálculo por vendedor | L17: rpc ventas_por_empleado | M17: Claude (QA automatizado) | N17: 2026-10-12
A18: DAS-007 | B18: Dashboard e Inicio | C18: Facturas realizadas | D18: Facturas emitidas/anuladas y fechas distintas. | E18: Comparar contador con regla de estados y período. | F18: Contador correcto según especificación. | G18: Alta | H18: Administrador | I18: Funcional | J18: Aprobado | K18: Contador del mes 18 = 18 emitidas (excluye 4 anuladas) | M18: Claude (QA automatizado) | N18: 2026-10-12
A19: DAS-008 | B19: Dashboard e Inicio | C19: Dashboard sin movimientos | D19: Entorno QA vacío. | E19: Abrir dashboard. | F19: Muestra ceros/estados vacíos sin errores. | G19: Media | H19: Administrador | I19: Usabilidad | J19: Aprobado | K19: Mes sin movimientos (mayo 2025): Ventas $0 · 0 facturas, Ingresos $0, Gastos $0, sin errores. | L19: Inicio admin, selector de mes | M19: Claude (QA automatizado) | N19: 2026-10-12
A20: DAS-009 | B20: Dashboard e Inicio | C20: Datos limitados a ventas propias | D20: Dos vendedores con ventas. | E20: Entrar como vendedor A y consultar resumen. | F20: Solo muestra datos autorizados de A. | G20: Crítica | H20: Vendedor | I20: Seguridad | J20: Aprobado | K20: El vendedor B no recibe ninguna venta del vendedor A (0 filas en facturas, ítems y resumen) | M20: Claude (QA automatizado) | N20: 2026-10-12
A21: DAS-010 | B21: Dashboard e Inicio | C21: Ocultar métricas administrativas al vendedor | D21: Sesión vendedor. | E21: Revisar Inicio, menús y búsquedas. | F21: No muestra ingresos globales, gastos, utilidad, valor monetario de inventario, ventas de otros ni comisiones. | G21: Crítica | H21: Vendedor | I21: Seguridad | J21: Aprobado | K21: Vendedor: Inicio, Inventario, Vender, Facturas, Historial, Clientes y Más sin «comisión», «utilidad», «gastos», «valor del inventario», «ingresos globales» ni costos. /finanzas, /proveedores, /empleados redirigen a Inicio. | L21: Búsqueda de texto en 9 pantallas | M21: Claude (QA automatizado) | N21: 2026-10-12
A22: DAS-011 | B22: Dashboard e Inicio | C22: Últimas facturas del vendedor | D22: Facturas de varios vendedores. | E22: Consultar últimas facturas. | F22: Solo muestra facturas autorizadas por política. | G22: Alta | H22: Vendedor | I22: Seguridad | J22: Aprobado | K22: «Mis últimas facturas» muestra solo FV-0019…0023 del propio vendedor; el filtro por vendedor_id se aplica en servidor y cliente. | L22: sellerHome.js + RLS | M22: Claude (QA automatizado) | N22: 2026-10-12
A23: DAS-012 | B23: Dashboard e Inicio | C23: Filtro de ventas propias | D23: Ventas del vendedor en distintos períodos. | E23: Cambiar día/mes/año. | F23: Refleja ventas propias del período elegido. | G23: Alta | H23: Vendedor | I23: Funcional | J23: Corregido | K23: Antes solo había Hoy / Esta semana / Este mes (faltaba año). Se agregó «Este año» con comparación vs. año anterior. Hoy $26.305.000 (3) · Mes y Año $28.860.000 (5) = API. | L23: InicioVendedor.jsx, sellerHome.js | M23: Claude (QA automatizado) | N23: 2026-10-12
A24: INV-001 | B24: Inventario | C24: Crear producto válido | D24: Formulario disponible. | E24: Completar campos obligatorios y guardar. | F24: Producto guardado y visible en inventario. | G24: Crítica | H24: Administrador / Vendedor | I24: Funcional | J24: Aprobado | K24: Productos creados: QA-FUNDA-IP15-NEG y QA-CABLE-USBC | L24: POST productos (admin) | M24: Claude (QA automatizado) | N24: 2026-10-12
A25: INV-002 | B25: Inventario | C25: Crear producto sin foto | D25: Imagen opcional. | E25: Crear producto sin adjuntar imagen. | F25: Permite guardar y muestra placeholder uniforme. | G25: Alta | H25: Administrador / Vendedor | I25: Funcional | J25: Aprobado | K25: Guardado sin foto_url (null); la tarjeta usa el placeholder común | L25: foto_url null | M25: Claude (QA automatizado) | N25: 2026-10-12
A26: INV-003 | B26: Inventario | C26: Validar campos obligatorios | D26: Formulario producto. | E26: Omitir nombre u otro campo obligatorio y guardar. | F26: Muestra validaciones y no guarda datos inválidos. | G26: Alta | H26: Administrador / Vendedor | I26: Funcional | J26: Aprobado | K26: Sin nombre → HTTP 400 «null value in column "nombre" of relation "productos" violates not-null constraint» | L26: NOT NULL nombre + validación del formulario | M26: Claude (QA automatizado) | N26: 2026-10-12
A27: INV-004 | B27: Inventario | C27: Generar SKU único | D27: SKU automático habilitado. | E27: Crear dos productos y comparar SKU. | F27: Cada producto tiene SKU único. | G27: Crítica | H27: Administrador / Vendedor | I27: Funcional | J27: Aprobado | K27: Segundo producto con el mismo SKU → HTTP 409 «duplicate key value violates unique constraint "productos_codigo_key"». La UI además busca un código libre (sufijo). | L27: unique(productos.codigo) + codigoLibre() en ProductoForm | M27: Claude (QA automatizado) | N27: 2026-10-12
A28: INV-005 | B28: Inventario | C28: Editar datos del producto | D28: Producto existente. | E28: Editar nombre/marca/modelo y guardar. | F28: Cambios persisten y se muestran correctamente. | G28: Alta | H28: Administrador / Vendedor | I28: Funcional | J28: Aprobado | K28: Tras editar y releer: {'nombre': 'QA Funda iPhone 15 Pro', 'marca': 'QA Marca', 'modelo': 'iPhone 15 Pro'} | L28: PATCH + GET | M28: Claude (QA automatizado) | N28: 2026-10-12
A29: INV-006 | B29: Inventario | C29: Guardar precios de compra y venta | D29: Producto nuevo/editable. | E29: Ingresar importes válidos y guardar. | F29: Importes correctos y visibles según permisos. | G29: Alta | H29: Administrador / Vendedor | I29: Funcional | J29: Aprobado | K29: Admin ve compra 1000 / venta 5000; vendedor ve solo precio_venta 5000 | L29: vista productos_venta sin costos | M29: Claude (QA automatizado) | N29: 2026-10-12
A30: INV-007 | B30: Inventario | C30: Categoría y compatibilidad | D30: Categorías disponibles. | E30: Crear funda para modelo específico y buscarla. | F30: Categoría, marca y compatibilidad se conservan. | G30: Alta | H30: Administrador / Vendedor | I30: Funcional | J30: Aprobado | K30: Búsqueda por modelo «iPhone 15»: [('QA Funda iPhone 15 Pro', 'Fundas', 'iPhone 15 Pro')] | L30: Categoría Fundas + modelo compatible | M30: Claude (QA automatizado) | N30: 2026-10-12
A31: INV-008 | B31: Inventario | C31: Buscar por nombre, SKU o marca | D31: Varios productos. | E31: Buscar por cada campo. | F31: Devuelve coincidencias correctas. | G31: Alta | H31: Administrador / Vendedor | I31: Funcional | J31: Aprobado | K31: Coincidencias por nombre:1, codigo:1, marca:2 | L31: Buscador de Inventario filtra nombre, SKU y marca | M31: Claude (QA automatizado) | N31: 2026-10-12
A32: INV-009 | B32: Inventario | C32: Filtros de categoría y stock | D32: Productos de varias categorías y estados. | E32: Aplicar filtros. | F32: Solo aparecen productos que cumplen criterios. | G32: Alta | H32: Administrador / Vendedor | I32: Funcional | J32: Aprobado | K32: Filtro Fundas → 2 productos, todos Fundas | L32: Hoja de filtros (categoría, marca, agotado/bajo) | M32: Claude (QA automatizado) | N32: 2026-10-12
... A40: INV-017 | B40: Inventario | C40: Validar precios inválidos | D40: Formulario producto. | E40: Ingresar precio negativo o formato inválido. | F40: Impide guardar importes inválidos. | G40: Alta | H40: Administrador / Vendedor | I40: Funcional | J40: Aprobado | K40: Precio -100 → HTTP 400 «new row for relation "productos" violates check constraint "productos_precio_venta_check"» | L40: check (precio_venta >= 0); MoneyInput solo admite dígitos | M40: Claude (QA automatizado) | N40: 2026-10-12
A41: INV-018 | B41: Inventario | C41: Persistencia de producto | D41: Producto guardado. | E41: Recargar y volver a entrar. | F41: Producto y datos permanecen guardados. | G41: Alta | H41: Administrador / Vendedor | I41: Funcional | J41: Aprobado | K41: Producto QA sigue guardado tras nueva sesión: QA Funda iPhone 15 Pro | M41: Claude (QA automatizado) | N41: 2026-10-12
A42: VEN-001 | B42: Ventas y carrito | C42: Iniciar nueva venta | D42: Sesión autorizada. | E42: Seleccionar Nueva venta. | F42: Abre flujo sin errores. | G42: Crítica | H42: Administrador / Vendedor | I42: Funcional | J42: Aprobado | K42: Nueva venta abre el punto de venta con «Tus más vendidos», categorías, marcas y buscador; sin errores. | L42: /vender | M42: Claude (QA automatizado) | N42: 2026-10-12
A43: VEN-002 | B43: Ventas y carrito | C43: Agregar producto al carrito | D43: Producto activo con stock. | E43: Buscar y agregar producto. | F43: Precio, cantidad y subtotal correctos. | G43: Crítica | H43: Administrador / Vendedor | I43: Funcional | J43: Aprobado | K43: Ítems: [(6, 2, 5000), (7, 1, 3000)]; subtotal 2×5.000 + 1×3.000 = 13000 | L43: Precio tomado del servidor | M43: Claude (QA automatizado) | N43: 2026-10-12
A44: VEN-003 | B44: Ventas y carrito | C44: Cambiar cantidad | D44: Producto en carrito y stock suficiente. | E44: Aumentar y reducir cantidad. | F44: Subtotales y total se recalculan correctamente. | G44: Alta | H44: Administrador / Vendedor | I44: Funcional | J44: Aprobado | K44: + / − recalculan: 2 → $10.000; tope en 11 = stock disponible ($55.000); al bajar vuelve a $10.000. | L44: Carrito POS | M44: Claude (QA automatizado) | N44: 2026-10-12
A45: VEN-004 | B45: Ventas y carrito | C45: Evitar vender más del stock | D45: Stock limitado. | E45: Intentar agregar cantidad superior a disponible. | F45: Bloquea exceso y explica el motivo. | G45: Crítica | H45: Administrador / Vendedor | I45: Funcional | J45: Aprobado | K45: Pedir 6 con stock 5 → HTTP 400 «Stock insuficiente para el producto 7 (disponible 5, solicitado 6)». En la UI el selector de cantidad se limita al stock. | L45: trigger de stock + POS | M45: Claude (QA automatizado) | N45: 2026-10-12
A46: VEN-005 | B46: Ventas y carrito | C46: Eliminar producto del carrito | D46: Carrito con varios productos. | E46: Eliminar una línea. | F46: Actualiza carrito y totales. | G46: Alta | H46: Administrador / Vendedor | I46: Funcional | J46: Aprobado | K46: Quitar línea pide confirmación y actualiza: 3 productos $13.000 → 2 productos $10.000. Se corrigió la tilde «Se quitarán». | L46: Vender.jsx | M46: Claude (QA automatizado) | N46: 2026-10-12
A47: VEN-006 | B47: Ventas y carrito | C47: Asociar cliente | D47: Cliente existente o creación disponible. | E47: Buscar y seleccionar cliente. | F47: Venta queda asociada al cliente correcto. | G47: Alta | H47: Administrador / Vendedor | I47: Funcional | J47: Aprobado | K47: Factura asociada al cliente 6 (QA Cliente Pruebas) | L47: facturas.cliente_id | M47: Claude (QA automatizado) | N47: 2026-10-12
...
